Workbook

Sheet 總覽
A1: Phonics 入門門檻測驗：題目藍圖（依前四週 Stage 1–3 複習詞表）
A2: 黃色儲存格為暫定門檻，是起始假設而非實證數字，需用現場資料校準後修改。
A4: 分測驗 | B4: 作答方式 | C4: 題數 | D4: 每題秒數（估） | E4: 時間（分） | F4: 通過門檻（比例） | G4: 通過所需題數 | H4: 門檻依據
A5: A 詞彙：第一階段詞 | B5: 聽單字，四圖選一 | C5: =COUNTIF(A_詞彙!B2:B33,"第一階段") -> 24 | D5: 8 | E5: =ROUND(C5*D5/60,1) -> 3.2 | F5: 0.8 | G5: =ROUNDUP(C5*F5,0) -> 20 | H5: 暫定；四選一猜中率 25%
A6: A 詞彙：對照詞 | B6: 聽單字，四圖選一 | C6: =COUNTIF(A_詞彙!B2:B33,"對照*") -> 8 | D6: 8 | E6: =ROUND(C6*D6/60,1) -> 1.1 | F6: 0.75 | G6: =ROUNDUP(C6*F6,0) -> 6 | H6: 暫定；用來確認孩子理解作答方式、有基本 DWE 詞彙
A7: B 音韻區辨：「不同」題 | B7: 聽兩個詞，判斷一樣或不一樣 | C7: =COUNTIF(B_音韻區辨!B2:B25,"不同") -> 16 | D7: 6 | E7: =ROUND(C7*D7/60,1) -> 1.6 | F7: 0.8 | G7: =ROUNDUP(C7*F7,0) -> 13 | H7: 暫定；需與「相同」題同時達標
A8: B 音韻區辨：「相同」題 | B8: 聽兩個詞，判斷一樣或不一樣 | C8: =COUNTIF(B_音韻區辨!B2:B25,"相同") -> 8 | D8: 6 | E8: =ROUND(C8*D8/60,1) -> 0.8 | F8: 0.75 | G8: =ROUNDUP(C8*F8,0) -> 6 | H8: 暫定；防止一律答「不同」
A9: C 句子理解 | B9: 聽句子，四圖選一 | C9: =COUNTA(C_句子理解!C2:C19) -> 18 | D9: 12 | E9: =ROUND(C9*D9/60,1) -> 3.6 | F9: 0.8 | G9: =ROUNDUP(C9*F9,0) -> 15 | H9: 暫定
A10: 合計 | C10: =SUM(C5:C9) -> 74 | E10: =SUM(E5:E9) -> 10.3 | H10: 不含練習題與語音指示，實際施測約再加 2 分鐘
A12: 結果判讀
A13: 結果型態 | B13: 解讀 | C13: 建議處置
A14: 對照詞未達標 | B14: 一般口語詞彙不足，或孩子不理解作答方式；結果不採計 | C14: 繼續累積輸入，之後重測
A15: 對照詞達標；第一階段詞未達標，錯誤多為音近干擾 | B15: 認得長詞但分不清短詞，詞彙表徵仍是整體輪廓 | C15: 先做最小對比詞的聽辨與口語活動，再進 Phonics
A16: 對照詞達標；第一階段詞未達標，錯誤多為義近或無關 | B16: 不認識這批詞 | C16: 各單元先用聽和圖預教目標詞，再進解碼
A17: A 達標；B 未達標 | B17: 認得詞，但聽不出特定音的差別 | C17: 依未通過的對比類別做聽辨訓練；Phonics 可同步開始
A18: A、B 達標；C 未達標 | B18: 單詞層級足夠，句子理解不足 | C18: 可進 Phonics，同時維持大量聽力輸入
A19: 全部達標 | B19: 達到入門門檻 | C19: 直接進 Phonics
A21: 詞表概況（前四週）
A22: 單字總數 | B22: =COUNTA(詞表分析!B2:B107) -> 106
A23: 圖像性高 | B23: =COUNTIF(詞表分析!C2:C107,"高") -> 52
A24: 圖像性中 | B24: =COUNTIF(詞表分析!C2:C107,"中") -> 42
A25: 圖像性低（不出詞彙題） | B25: =COUNTIF(詞表分析!C2:C107,"低") -> 12
A26: 表內最小對比詞組數 | B26: =COUNTA(最小對比詞!A2:A77) -> 76
A27: 至少有一個表內最小對比詞的單字數 | B27: =COUNTIF(詞表分析!D2:D107,">0") -> 65

Sheet A_詞彙
A1: 題號 | B1: 組別 | C1: 所屬週 | D1: 目標詞（播放） | E1: 音近干擾 | F1: 對比位置 | G1: 對比音 | H1: 義近干擾 | I1: 無關干擾 | J1: 備註
A2: A01 | B2: 第一階段 | C2: 1 | D2: cat | E2: cut | F2: 母音 | G2: æ / ʌ | H2: dog | I2: sun
A3: A02 | B3: 第一階段 | C3: 1 | D3: pig | E3: pin | F3: 字尾 | G3: g / n | H3: duck | I3: bed
A4: A03 | B4: 第一階段 | C4: 2 | D4: hat | E4: hot | F4: 母音 | G4: æ / ɑ | H4: sock | I4: egg
A5: A04 | B5: 第一階段 | C5: 2 | D5: bat | E5: bag | F5: 字尾 | G5: t / g | H5: ball | I5: nest | J5: bat 的圖為球棒（詞義已確認與 DWE 相符）
A6: A05 | B6: 第一階段 | C6: 2 | D6: bed | E6: shed | F6: 字首 | G6: b / ʃ | H6: pillow | I6: frog
A7: A06 | B7: 第一階段 | C7: 2 | D7: pin | E7: pan | F7: 母音 | G7: ɪ / æ | H7: nail | I7: cow
A8: A07 | B8: 第一階段 | C8: 2 | D8: leg | E8: log | F8: 母音 | G8: ɛ / ɔ | H8: hand | I8: bus
A9: A08 | B9: 第一階段 | C9: 2 | D9: man | E9: mat | F9: 字尾 | G9: n / t | H9: boy | I9: clock
A10: A09 | B10: 第一階段 | C10: 2 | D10: sun | E10: run | F10: 字首 | G10: s / r | H10: moon | I10: desk
A11: A10 | B11: 第一階段 | C11: 2 | D11: king | E11: ring | F11: 字首 | G11: k / r | H11: man | I11: fish
A12: A11 | B12: 第一階段 | C12: 2 | D12: egg | E12: leg | F12: 韻腳相同 | G12: ∅ / l | H12: milk | I12: drum | J12: 非最小對比：多一個字首子音
A13: A12 | B13: 第一階段 | C13: 2 | D13: sit | E13: sing | F13: 字尾 | G13: t / ŋ | H13: stand | I13: box
A14: A13 | B14: 第一階段 | C14: 3 | D14: glass | E14: grass | F14: 子音叢 | G14: l / r | H14: cup | I14: dress
A15: A14 | B15: 第一階段 | C15: 3 | D15: hand | E15: band | F15: 字首 | G15: h / b | H15: foot | I15: tent | J15: band 的圖為樂團（詞義已確認與 DWE 相符）
A16: A15 | B16: 第一階段 | C16: 3 | D16: swing | E16: swim | F16: 字尾 | G16: ŋ / m | H16: sled | I16: bag
A17: A16 | B17: 第一階段 | C17: 3 | D17: frog | E17: log | F17: 韻腳相同 | G17: fr / l | H17: duck | I17: desk | J17: 非最小對比：子音叢 vs 單子音
A18: A17 | B18: 第一階段 | C18: 3 | D18: nest | E18: neck | F18: 字尾 | G18: st / k | H18: bird | I18: box | J18: 非最小對比：字尾子音叢
A19: A18 | B19: 第一階段 | C19: 3 | D19: string | E19: strong | F19: 母音 | G19: ɪ / ɔ | H19: rope | I19: pig
A20: A19 | B20: 第一階段 | C20: 4 | D20: shell | E20: well | F20: 字首 | G20: ʃ / w | H20: fish | I20: plant | J20: well 的圖為水井（詞義已確認與 DWE 相符）
A21: A20 | B21: 第一階段 | C21: 4 | D21: sock | E21: sick | F21: 母音 | G21: ɑ / ɪ | H21: shoe | I21: cow
A22: A21 | B22: 第一階段 | C22: 4 | D22: lock | E22: clock | F22: 子音叢 | G22: l / kl | H22: key | I22: drum | J22: 非最小對比：子音叢 vs 單子音
A23: A22 | B23: 第一階段 | C23: 4 | D23: brush | E23: branch | F23: 字首相同 | G23: ʌʃ / æntʃ | H23: soap | I23: tent | J23: 非最小對比：共用字首 br-
A24: A23 | B24: 第一階段 | C24: 4 | D24: track | E24: crack | F24: 子音叢 | G24: tr / kr | H24: train | I24: cup | J24: track 的圖為鐵軌（詞義已確認與 DWE 相符）
A25: A24 | B25: 第一階段 | C25: 4 | D25: chin | E25: thin | F25: 字首 | G25: tʃ / θ | H25: neck | I25: bus | J25: thin 的圖為瘦的人
A26: A25 | B26: 對照（後段多音節） | C26: 20 | D26: elephant | E26: （無） | F26: — | G26: — | H26: giraffe | I26: tomato / piano | J26: 對照題無音近干擾，改為兩個無關詞
A27: A26 | B27: 對照（後段多音節） | C27: 15 | D27: banana | E27: （無） | F27: — | G27: — | H27: orange | I27: zebra / pillow | J27: 對照題無音近干擾，改為兩個無關詞
A28: A27 | B28: 對照（後段多音節） | C28: 20 | D28: umbrella | E28: （無） | F28: — | G28: — | H28: jacket | I28: lemon / tiger | J28: 對照題無音近干擾，改為兩個無關詞
A29: A28 | B29: 對照（後段多音節） | C29: 20 | D29: butterfly | E29: （無） | F29: — | G29: — | H29: bee | I29: bottle / ladder | J29: 對照題無音近干擾，改為兩個無關詞
A30: A29 | B30: 對照（後段多音節） | C30: 15 | D30: rabbit | E30: （無） | F30: — | G30: — | H30: kitten | I30: candle / sweater | J30: 對照題無音近干擾，改為兩個無關詞
A31: A30 | B31: 對照（後段多音節） | C31: 18 | D31: apple | E31: （無） | F31: — | G31: — | H31: cherry | I31: turtle / mirror | J31: 對照題無音近干擾，改為兩個無關詞
A32: A31 | B32: 對照（後段多音節） | C32: 17 | D32: window | E32: （無） | F32: — | G32: — | H32: door | I32: spoon / rooster | J32: 對照題無音近干擾，改為兩個無關詞
A33: A32 | B33: 對照（後段多音節） | C33: 17 | D33: monkey | E33: （無） | F33: — | G33: — | H33: kangaroo | I33: basket / flower | J33: 對照題無音近干擾，改為兩個無關詞

Sheet B_音韻區辨
A1: 題號 | B1: 正解 | C1: 詞 1 | D1: 詞 2 | E1: 對比類別 | F1: 對比音 | G1: 表外詞
A2: B01 | B2: 不同 | C2: pin | D2: pan | E2: 母音 | F2: ɪ / æ
A3: B02 | B3: 不同 | C3: cat | D3: cut | E3: 母音 | F3: æ / ʌ
A4: B03 | B4: 不同 | C4: hat | D4: hot | E4: 母音 | F4: æ / ɑ
A5: B04 | B5: 不同 | C5: leg | D5: log | E5: 母音 | F5: ɛ / ɔ
A6: B05 | B6: 不同 | C6: bed | D6: bad | E6: 母音 | F6: ɛ / æ | G6: 是：bad
A7: B06 | B7: 不同 | C7: man | D7: men | E7: 母音 | F7: æ / ɛ | G7: 是：men
A8: B07 | B8: 不同 | C8: cup | D8: cut | E8: 字尾 | F8: p / t（部位）
A9: B08 | B9: 不同 | C9: bat | D9: bag | E9: 字尾 | F9: t / g（部位）
A10: B09 | B10: 不同 | C10: pig | D10: pick | E10: 字尾 | F10: g / k（清濁）
A11: B10 | B11: 不同 | C11: mat | D11: mad | E11: 字尾 | F11: t / d（清濁） | G11: 是：mad
A12: B11 | B12: 不同 | C12: swim | D12: swing | E12: 字尾 | F12: m / ŋ（鼻音）
A13: B12 | B13: 不同 | C13: thin | D13: thing | E13: 字尾 | F13: n / ŋ（鼻音） | G13: 是：thing
A14: B13 | B14: 不同 | C14: sell | D14: shell | E14: 字首 | F14: s / ʃ
A15: B14 | B15: 不同 | C15: think | D15: sink | E15: 字首 | F15: θ / s | G15: 是：sink
A16: B15 | B16: 不同 | C16: glass | D16: grass | E16: 子音叢 | F16: l / r
A17: B16 | B17: 不同 | C17: crack | D17: track | E17: 子音叢 | F17: kr / tr
A18: B17 | B18: 相同 | C18: cat | D18: cat | E18: — | F18: —
A19: B18 | B19: 相同 | C19: pin | D19: pin | E19: — | F19: —
A20: B19 | B20: 相同 | C20: bed | D20: bed | E20: — | F20: —
A21: B20 | B21: 相同 | C21: sun | D21: sun | E21: — | F21: —
A22: B21 | B22: 相同 | C22: ring | D22: ring | E22: — | F22: —
A23: B22 | B23: 相同 | C23: shell | D23: shell | E23: — | F23: —
A24: B23 | B24: 相同 | C24: grass | D24: grass | E24: — | F24: —
A25: B24 | B25: 相同 | C25: sock | D25: sock | E25: — | F25: —
A27: 說明
A28: 題號為題庫編號，施測時隨機排序，「相同」與「不同」穿插。
A29: 「相同」題請用同一個詞的兩次不同錄音，避免孩子靠聲學上完全一致來判斷。
A30: 表外詞只用於聽辨，不需要圖片，也不要求孩子認識該詞。
A31: ɛ/æ、字尾 n/ŋ、字尾清濁在前四週詞表內沒有最小對比詞，因此借用表外詞。

Sheet C_句子理解
A1: 題號 | B1: 層級 | C1: 句子（播放） | D1: 正解圖 | E1: 干擾圖 1：換主詞 | F1: 干擾圖 2：換動作、屬性或位置關係 | G1: 干擾圖 3：換地點或受詞
A2: C01 | B2: 1 | C2: The cat sits on the mat. | D2: 貓坐在墊子上 | E2: 狗坐在墊子上 | F2: 貓站在墊子上 | G2: 貓坐在床上
A3: C02 | B3: 1 | C3: The dog runs up the hill. | D3: 狗跑上山丘 | E3: 豬跑上山丘 | F3: 狗坐在山丘上 | G3: 狗跑向箱子
A4: C03 | B4: 1 | C4: The pig sits in the sun. | D4: 豬坐在太陽下 | E4: 狗坐在太陽下 | F4: 豬在太陽下跑 | G4: 豬坐在箱子裡
A5: C04 | B5: 1 | C5: The man cuts the log. | D5: 男人砍木頭 | E5: 國王砍木頭 | F5: 男人拉木頭 | G5: 男人切蛋
A6: C05 | B6: 1 | C6: The egg is in the pan. | D6: 蛋在鍋子裡 | E6: 魚在鍋子裡 | F6: 蛋在鍋子旁邊 | G6: 蛋在杯子裡
A7: C06 | B7: 1 | C7: The king pulls the bag. | D7: 國王拉袋子 | E7: 男人拉袋子 | F7: 國王抱著袋子 | G7: 國王拉箱子
A8: C07 | B8: 2 | C8: The duck is on the log. | D8: 鴨子在木頭上 | E8: 青蛙在木頭上 | F8: 鴨子在木頭旁游泳 | G8: 鴨子在雪橇上
A9: C08 | B9: 2 | C9: The frog swims in the pond. | D9: 青蛙在池塘裡游 | E9: 魚在池塘裡游 | F9: 青蛙坐在池塘邊 | G9: 青蛙在玻璃杯裡游
A10: C09 | B10: 2 | C10: The king has a ring on his hand. | D10: 國王手上有戒指 | E10: 男人手上有戒指 | F10: 國王手上拿杯子 | G10: 國王腿上有戒指
A11: C10 | B11: 2 | C11: The sock is in the box. | D11: 襪子在箱子裡 | E11: 帽子在箱子裡 | F11: 襪子在箱子上 | G11: 襪子在袋子裡
A12: C11 | B12: 2 | C12: The cat licks the fish. | D12: 貓舔魚 | E12: 狗舔魚 | F12: 貓聞魚 | G12: 貓舔牛奶
A13: C12 | B13: 2 | C13: The pig runs in the grass. | D13: 豬在草地上跑 | E13: 狗在草地上跑 | F13: 豬坐在草地上 | G13: 豬在池塘邊跑
... A19: C18 | B19: 3 | C19: The strong man lifts the big drum. | D19: 強壯的男人抬大鼓 | E19: 強壯的國王抬大鼓 | F19: 瘦弱的男人抬大鼓 | G19: 強壯的男人抬大箱子
A21: 說明
A22: 層級 1：實詞全部取自第 1–2 週（CVC 詞），無修飾語；層級 2：含第 3–4 週詞彙（子音叢、雙字母），無修飾語；層級 3：名詞帶形容詞修飾語。
A23: 句中實詞全部取自前四週詞表；功能詞只用 the, a, on, in, has, his, is, up。
A24: 三張干擾圖各只改變一個成分，孩子必須聽懂整句才能選對；錯選哪一張即可看出漏聽哪個成分。

Sheet 詞表分析
A1: 週 | B1: 單字 | C1: 圖像性 | D1: 表內最小對比詞數 | E1: 表內最小對比詞 | F1: 在測驗中的用途
A2: 1 | B2: cat | C2: 高 | D2: 5 | E2: hat, mat, bat, cut, fat | F2: A 目標、B、C
A3: 1 | B3: cup | C3: 高 | D3: 1 | E3: cut | F3: A 干擾、B
A4: 1 | B4: dog | C4: 高 | D4: 2 | E4: dig, log | F4: A 干擾、C
A5: 1 | B5: big | C5: 中 | D5: 3 | E5: pig, dig, bag | F5: C
A6: 1 | B6: pig | C6: 高 | D6: 4 | E6: big, dig, pin, pick | F6: A 目標、B、C
A7: 1 | B7: dig | C7: 中 | D7: 3 | E7: dog, big, pig | F7: C
A8: 2 | B8: hat | C8: 高 | D8: 6 | E8: cat, mat, bat, hot, fat, hit | F8: A 目標、B、C
A9: 2 | B9: mat | C9: 高 | D9: 5 | E9: cat, hat, bat, man, fat | F9: A 干擾、B、C
A10: 2 | B10: bat | C10: 高 | D10: 5 | E10: cat, hat, mat, bag, fat | F10: A 目標、B
A11: 2 | B11: bed | C11: 高 | D11: 2 | E11: red, shed | F11: A 目標、B、C
A12: 2 | B12: pin | C12: 高 | D12: 5 | E12: pig, pan, chin, thin, pick | F12: A 目標、B
A13: 2 | B13: sit | C13: 中 | D13: 4 | E13: sing, hit, fit, sick | F13: A 目標、C
A14: 2 | B14: hip | C14: 中 | D14: 2 | E14: hill, hit
A15: 2 | B15: leg | C15: 高 | D15: 1 | E15: log | F15: A 目標、B
A16: 2 | B16: bag | C16: 高 | D16: 2 | E16: big, bat | F16: A 干擾、B、C
A17: 2 | B17: pan | C17: 高 | D17: 3 | E17: pin, man, pack | F17: A 干擾、B、C
A18: 2 | B18: box | C18: 高 | D18: 0 | F18: A 干擾、C
A19: 2 | B19: log | C19: 高 | D19: 3 | E19: dog, leg, long | F19: A 干擾、B、C
A20: 2 | B20: man | C20: 高 | D20: 2 | E20: mat, pan | F20: A 目標、B、C
A21: 2 | B21: bus | C21: 高 | D21: 0 | F21: A 干擾
A22: 2 | B22: sun | C22: 高 | D22: 1 | E22: run | F22: A 目標、B、C
A23: 2 | B23: run | C23: 中 | D23: 2 | E23: sun, rush | F23: A 干擾、C
A24: 2 | B24: cut | C24: 中 | D24: 2 | E24: cat, cup | F24: A 干擾、B、C
A25: 2 | B25: hot | C25: 中 | D25: 2 | E25: hat, hit | F25: A 干擾、B
A26: 2 | B26: red | C26: 中 | D26: 2 | E26: bed, shed | F26: C
A27: 2 | B27: wet | C27: 中 | D27: 1 | E27: well | F27: C
A28: 2 | B28: fat | C28: 中 | D28: 5 | E28: cat, hat, mat, bat, fit
A29: 2 | B29: sad | C29: 中 | D29: 0 | F29: C
A30: 2 | B30: egg | C30: 高 | D30: 0 | F30: A 目標、C
A31: 2 | B31: hill | C31: 高 | D31: 2 | E31: hip, hit | F31: C
A32: 2 | B32: well | C32: 高 | D32: 3 | E32: wet, sell, shell | F32: A 干擾
A33: 2 | B33: ring | C33: 高 | D33: 2 | E33: king, sing | F33: A 干擾、B、C
A34: 2 | B34: king | C34: 高 | D34: 3 | E34: ring, sing, kiss | F34: A 目標、C
A35: 2 | B35: sing | C35: 中 | D35: 4 | E35: sit, ring, king, sick | F35: A 干擾
A36: 2 | B36: full | C36: 低 | D36: 1 | E36: pull
A37: 2 | B37: kiss | C37: 中 | D37: 2 | E37: king, miss
A38: 2 | B38: sell | C38: 中 | D38: 2 | E38: well, shell | F38: B
A39: 2 | B39: ax | C39: 高 | D39: 0
A40: 2 | B40: pull | C40: 中 | D40: 2 | E40: full, push | F40: C
...

Sheet 最小對比詞
A1: 詞 1 | B1: 詞 2 | C1: 差異位置 | D1: 音 1（ARPAbet） | E1: 音 2（ARPAbet）
A2: cat | B2: hat | C2: 字首 | D2: K | E2: HH
A3: cat | B3: mat | C3: 字首 | D3: K | E3: M
A4: cat | B4: bat | C4: 字首 | D4: K | E4: B
A5: cat | B5: cut | C5: 中間 | D5: AE | E5: AH
A6: cat | B6: fat | C6: 字首 | D6: K | E6: F
A7: cup | B7: cut | C7: 字尾 | D7: P | E7: T
A8: dog | B8: dig | C8: 中間 | D8: AO | E8: IH
A9: dog | B9: log | C9: 字首 | D9: D | E9: L
A10: big | B10: pig | C10: 字首 | D10: B | E10: P
A11: big | B11: dig | C11: 字首 | D11: B | E11: D
A12: big | B12: bag | C12: 中間 | D12: IH | E12: AE
... A77: crack | B77: track | C77: 字首 | D77: K | E77: T
A79: 依 CMU 發音詞典（美式發音）計算：兩詞音素數相同且只差一個音素。

Sheet 作答紀錄欄位
A1: 欄位 | B1: 說明 | C1: 範例
A2: token | B2: 學生代碼，與 ORF 測驗共用，用來串接後續 ORF 成績 | C2: S0123
A3: attempt_at | B3: 作答時間；每次施測新增列，不覆寫 | C3: 2026-10-03 09:15
A4: item_id | B4: 題號 | C4: A07
A5: response | B5: 孩子選的選項 | C5: log
A6: correct | B6: 是否答對（1 / 0） | C6: 0
A7: error_type | B7: A：音近 / 義近 / 無關；B：漏報 / 誤報；C：主詞 / 動作屬性 / 地點受詞 | C7: 音近
A8: rt_ms | B8: 從音檔播完到點選的毫秒數 | C8: 2140
A9: replays | B9: 重播次數 | C9: 1
